Workbook

Sheet Dashboard
A1: Clothing Production Planning Database
A2: Last refreshed | B2: =TODAY() -> 46169
A3: Input source | B3: sample_planning test 2.xlsx + cleaned planning database
A5: KPI | B5: Value
A6: Total orders | B6: =COUNTA(orders!A2:A1000) -> 60
A7: Total units | B7: =SUM(orders!E2:E1000) -> 20600
A8: Average progress | B8: =AVERAGE(orders!N2:N1000) -> 0.441
A9: High/overdue risk orders | B9: =COUNTIF(orders!S2:S1000,"HIGH")+COUNTIF(orders!S2:S1000,"OVERDUE") -> 0
A10: Open TNA milestones | B10: =COUNTIF(TNA_calendar!G2:G2000,"Open") -> 231
A11: Potential phase bottlenecks | B11: =COUNTIF(phase_capacity!J2:J1000,"Potential bottleneck") -> 127
A13: Risk level | B13: Order count
A14: LOW | B14: =COUNTIF(orders!S2:S1000,A14) -> 60
A15: MEDIUM | B15: =COUNTIF(orders!S2:S1000,A15) -> 0
A16: HIGH | B16: =COUNTIF(orders!S2:S1000,A16) -> 0
A17: OVERDUE | B17: =COUNTIF(orders!S2:S1000,A17) -> 0
A20: Product type | B20: Order count | C20: Units
A21: Cappotto | B21: =COUNTIF(orders!D2:D1000,A21) -> 6 | C21: =SUMIF(orders!D2:D1000,A21,orders!E2:E1000) -> 1710
A22: Gonna | B22: =COUNTIF(orders!D2:D1000,A22) -> 4 | C22: =SUMIF(orders!D2:D1000,A22,orders!E2:E1000) -> 1190
A23: Camicia | B23: =COUNTIF(orders!D2:D1000,A23) -> 3 | C23: =SUMIF(orders!D2:D1000,A23,orders!E2:E1000) -> 1320
A24: Abito | B24: =COUNTIF(orders!D2:D1000,A24) -> 5 | C24: =SUMIF(orders!D2:D1000,A24,orders!E2:E1000) -> 910
A25: Jeans | B25: =COUNTIF(orders!D2:D1000,A25) -> 10 | C25: =SUMIF(orders!D2:D1000,A25,orders!E2:E1000) -> 3250
A26: T-shirt | B26: =COUNTIF(orders!D2:D1000,A26) -> 4 | C26: =SUMIF(orders!D2:D1000,A26,orders!E2:E1000) -> 1450
A27: Pantalone | B27: =COUNTIF(orders!D2:D1000,A27) -> 3 | C27: =SUMIF(orders!D2:D1000,A27,orders!E2:E1000) -> 1440
A28: Blazer | B28: =COUNTIF(orders!D2:D1000,A28) -> 4 | C28: =SUMIF(orders!D2:D1000,A28,orders!E2:E1000) -> 1140
A29: Felpa | B29: =COUNTIF(orders!D2:D1000,A29) -> 1 | C29: =SUMIF(orders!D2:D1000,A29,orders!E2:E1000) -> 300
A30: Top | B30: =COUNTIF(orders!D2:D1000,A30) -> 5 | C30: =SUMIF(orders!D2:D1000,A30,orders!E2:E1000) -> 1520
A31: Kimono | B31: =COUNTIF(orders!D2:D1000,A31) -> 3 | C31: =SUMIF(orders!D2:D1000,A31,orders!E2:E1000) -> 1190
A32: Body | B32: =COUNTIF(orders!D2:D1000,A32) -> 3 | C32: =SUMIF(orders!D2:D1000,A32,orders!E2:E1000) -> 1420

Sheet style_master
A1: style_id | B1: style_name | C1: product_type | D1: category | E1: material_family | F1: size_range | G1: complexity_score | H1: estimated_smv | I1: tech_pack_status
A2: STY-001-1 | B2: Cappotto Navy | C2: Cappotto | D2: Outerwear | E2: wool blend | F2: 34-44 | G2: 5 | H2: 85 | I2: Needs update
A3: STY-001-2 | B3: Cappotto Chocolate | C3: Cappotto | D3: Outerwear | E3: wool blend | F3: 1-5 | G3: 5 | H3: 89 | I3: Needs update
A4: STY-002-1 | B4: Gonna Chocolate | C4: Gonna | D4: Bottoms | E4: viscose twill | F4: IT38-IT48 | G4: 2 | H4: 22 | I4: Draft
A5: STY-002-2 | B5: Gonna Sage | C5: Gonna | D5: Bottoms | E5: viscose twill | F5: XS-XL | G5: 2 | H5: 24 | I5: Draft
A6: STY-003-1 | B6: Camicia Sage | C6: Camicia | D6: Tops/Dresses | E6: organic cotton poplin | F6: XS-XL | G6: 3 | H6: 34 | I6: Needs update
A7: STY-003-2 | B7: Camicia Burgundy | C7: Camicia | D7: Tops/Dresses | E7: organic cotton poplin | F7: IT38-IT48 | G7: 3 | H7: 36 | I7: Approved
A8: STY-004-1 | B8: Abito Burgundy | C8: Abito | D8: Tops/Dresses | E8: tencel satin | F8: 36-46 | G8: 4 | H8: 48 | I8: Needs update
A9: STY-004-2 | B9: Abito Powder Blue | C9: Abito | D9: Tops/Dresses | E9: tencel satin | F9: S-XXL | G9: 4 | H9: 50 | I9: Needs update
A10: STY-005-1 | B10: Jeans Powder Blue | C10: Jeans | D10: Bottoms | E10: organic denim | F10: IT38-IT48 | G10: 4 | H10: 41 | I10: Draft
A11: STY-005-2 | B11: Jeans Charcoal | C11: Jeans | D11: Bottoms | E11: organic denim | F11: 36-46 | G11: 4 | H11: 43 | I11: Draft
A12: STY-006-1 | B12: T-shirt Charcoal | C12: T-shirt | D12: Tops/Dresses | E12: organic cotton jersey | F12: 1-5 | G12: 1 | H12: 18 | I12: Needs update
A13: STY-006-2 | B13: T-shirt Sand | C13: T-shirt | D13: Tops/Dresses | E13: organic cotton jersey | F13: S-XXL | G13: 1 | H13: 21 | I13: Approved
... A33: STY-016-2 | B33: Baby doll Powder Blue | C33: Baby doll | D33: Underwear | E33: tencel satin | F33: S-XXL | G33: 4 | H33: 39 | I33: Approved

Sheet orders
A1: order_id | B1: client | C1: style_id | D1: product_type | E1: quantity | F1: size_range | G1: start_date | H1: deadline | I1: ex_factory_date | J1: assigned_lab | K1: assigned_line | L1: priority | M1: status | N1: progress_percentage | O1: planned_smv | P1: total_standard_minutes | Q1: capacity_days_needed | R1: days_to_deadline | S1: on_time_risk
A2: ORD-1010 | B2: Sartoria Napoli | C2: STY-001-2 | D2: Cappotto | E2: 180 | F2: 1-5 | G2: 46174 | H2: 46191 | I2: 46189 | J2: L3 | K2: LN-011 | L2: normal | M2: materials pending | N2: 0.05 | O2: =IFERROR(VLOOKUP(C2,style_master!$A:$H,8,FALSE),0) -> 89 | P2: =E2*O2 -> 16020 | Q2: =IFERROR(P2/SUMIFS(line_capacity!$N:$N,line_capacity!$A:$A,J2,line_capacity!$B:$B,K2),0) -> 9.0447154 | R2: =H2-TODAY() -> 22 | S2: =IF(R2<0,"OVERDUE",IF(Q2>R2,"HIGH",IF(R2-Q2<3,"MEDIUM","LOW"))) -> LOW
A3: ORD-1011 | B3: Atelier Bologna | C3: STY-002-1 | D3: Gonna | E3: 240 | F3: IT38-IT48 | G3: 46174 | H3: 46186 | I3: 46184 | J3: L3 | K3: LN-011 | L3: high | M3: shipped | N3: 0 | O3: =IFERROR(VLOOKUP(C3,style_master!$A:$H,8,FALSE),0) -> 22 | P3: =E3*O3 -> 5280 | Q3: =IFERROR(P3/SUMIFS(line_capacity!$N:$N,line_capacity!$A:$A,J3,line_capacity!$B:$B,K3),0) -> 2.9810298 | R3: =H3-TODAY() -> 17 | S3: =IF(R3<0,"OVERDUE",IF(Q3>R3,"HIGH",IF(R3-Q3<3,"MEDIUM","LOW"))) -> LOW
A4: ORD-1012 | B4: Boutique Genova | C4: STY-003-2 | D4: Camicia | E4: 500 | F4: IT38-IT48 | G4: 46175 | H4: 46194 | I4: 46192 | J4: L4 | K4: LN-016 | L4: normal | M4: ready to ship | N4: 0.12 | O4: =IFERROR(VLOOKUP(C4,style_master!$A:$H,8,FALSE),0) -> 36 | P4: =E4*O4 -> 18000 | Q4: =IFERROR(P4/SUMIFS(line_capacity!$N:$N,line_capacity!$A:$A,J4,line_capacity!$B:$B,K4),0) -> 7.7170021 | R4: =H4-TODAY() -> 25 | S4: =IF(R4<0,"OVERDUE",IF(Q4>R4,"HIGH",IF(R4-Q4<3,"MEDIUM","LOW"))) -> LOW
A5: ORD-1013 | B5: Moda Verona | C5: STY-004-2 | D5: Abito | E5: 150 | F5: S-XXL | G5: 46176 | H5: 46184 | I5: 46182 | J5: L3 | K5: LN-011 | L5: urgent | M5: not started | N5: 0 | O5: =IFERROR(VLOOKUP(C5,style_master!$A:$H,8,FALSE),0) -> 50 | P5: =E5*O5 -> 7500 | Q5: =IFERROR(P5/SUMIFS(line_capacity!$N:$N,line_capacity!$A:$A,J5,line_capacity!$B:$B,K5),0) -> 4.2344173 | R5: =H5-TODAY() -> 15 | S5: =IF(R5<0,"OVERDUE",IF(Q5>R5,"HIGH",IF(R5-Q5<3,"MEDIUM","LOW"))) -> LOW
A6: ORD-1014 | B6: Casa Palermo | C6: STY-005-1 | D6: Jeans | E6: 320 | F6: IT38-IT48 | G6: 46174 | H6: 46189 | I6: 46187 | J6: L4 | K6: LN-016 | L6: normal | M6: shipped | N6: 0.03 | O6: =IFERROR(VLOOKUP(C6,style_master!$A:$H,8,FALSE),0) -> 41 | P6: =E6*O6 -> 13120 | Q6: =IFERROR(P6/SUMIFS(line_capacity!$N:$N,line_capacity!$A:$A,J6,line_capacity!$B:$B,K6),0) -> 5.6248371 | R6: =H6-TODAY() -> 20 | S6: =IF(R6<0,"OVERDUE",IF(Q6>R6,"HIGH",IF(R6-Q6<3,"MEDIUM","LOW"))) -> LOW
A7: ORD-1106 | B7: Sartoria Napoli | C7: STY-012-2 | D7: Body | E7: 300 | F7: 34-44 | G7: 46209 | H7: 46233 | I7: 46231 | J7: L8 | K7: LN-035 | L7: normal | M7: not started | N7: 0.63 | O7: =IFERROR(VLOOKUP(C7,style_master!$A:$H,8,FALSE),0) -> 32 | P7: =E7*O7 -> 9600 | Q7: =IFERROR(P7/SUMIFS(line_capacity!$N:$N,line_capacity!$A:$A,J7,line_capacity!$B:$B,K7),0) -> 2.6832671 | R7: =H7-TODAY() -> 64 | S7: =IF(R7<0,"OVERDUE",IF(Q7>R7,"HIGH",IF(R7-Q7<3,"MEDIUM","LOW"))) -> LOW
A8: ORD-1107 | B8: Atelier Bologna | C8: STY-005-1 | D8: Jeans | E8: 1000 | F8: IT38-IT48 | G8: 46244 | H8: 46269 | I8: 46263 | J8: L4 | K8: LN-016 | L8: normal | M8: not started | N8: 0.31 | O8: =IFERROR(VLOOKUP(C8,style_master!$A:$H,8,FALSE),0) -> 41 | P8: =E8*O8 -> 41000 | Q8: =IFERROR(P8/SUMIFS(line_capacity!$N:$N,line_capacity!$A:$A,J8,line_capacity!$B:$B,K8),0) -> 17.577616 | R8: =H8-TODAY() -> 100 | S8: =IF(R8<0,"OVERDUE",IF(Q8>R8,"HIGH",IF(R8-Q8<3,"MEDIUM","LOW"))) -> LOW
A9: ORD-1108 | B9: Boutique Genova | C9: STY-005-2 | D9: Jeans | E9: 120 | F9: 36-46 | G9: 46258 | H9: 46271 | I9: 46268 | J9: L1 | K9: LN-002 | L9: normal | M9: quality control | N9: 0.75 | O9: =IFERROR(VLOOKUP(C9,style_master!$A:$H,8,FALSE),0) -> 43 | P9: =E9*O9 -> 5160 | Q9: =IFERROR(P9/SUMIFS(line_capacity!$N:$N,line_capacity!$A:$A,J9,line_capacity!$B:$B,K9),0) -> 2.7820911 | R9: =H9-TODAY() -> 102 | S9: =IF(R9<0,"OVERDUE",IF(Q9>R9,"HIGH",IF(R9-Q9<3,"MEDIUM","LOW"))) -> LOW
A10: ORD-1109 | B10: Venezia Atelier | C10: STY-005-2 | D10: Jeans | E10: 120 | F10: 36-46 | G10: 46269 | H10: 46285 | I10: 46280 | J10: L8 | K10: LN-035 | L10: normal | M10: shipped | N10: 0.49 | O10: =IFERROR(VLOOKUP(C10,style_master!$A:$H,8,FALSE),0) -> 43 | P10: =E10*O10 -> 5160 | Q10: =IFERROR(P10/SUMIFS(line_capacity!$N:$N,line_capacity!$A:$A,J10,line_capacity!$B:$B,K10),0) -> 1.4422561 | R10: =H10-TODAY() -> 116 | S10: =IF(R10<0,"OVERDUE",IF(Q10>R10,"HIGH",IF(R10-Q10<3,"MEDIUM","LOW"))) -> LOW
A11: ORD-1110 | B11: Linea Roma | C11: STY-002-2 | D11: Gonna | E11: 650 | F11: XS-XL | G11: 46177 | H11: 46192 | I11: 46187 | J11: L7 | K11: LN-030 | L11: high | M11: shipped | N11: 0.65 | O11: =IFERROR(VLOOKUP(C11,style_master!$A:$H,8,FALSE),0) -> 24 | P11: =E11*O11 -> 15600 | Q11: =IFERROR(P11/SUMIFS(line_capacity!$N:$N,line_capacity!$A:$A,J11,line_capacity!$B:$B,K11),0) -> 2.9761905 | R11: =H11-TODAY() -> 23 | S11: =IF(R11<0,"OVERDUE",IF(Q11>R11,"HIGH",IF(R11-Q11<3,"MEDIUM","LOW"))) -> LOW
A12: ORD-1111 | B12: Boutique Genova | C12: STY-005-1 | D12: Jeans | E12: 220 | F12: IT38-IT48 | G12: 46253 | H12: 46305 | I12: 46299 | J12: L9 | K12: LN-039 | L12: normal | M12: shipped | N12: 0.36 | O12: =IFERROR(VLOOKUP(C12,style_master!$A:$H,8,FALSE),0) -> 41 | P12: =E12*O12 -> 9020 | Q12: =IFERROR(P12/SUMIFS(line_capacity!$N:$N,line_capacity!$A:$A,J12,line_capacity!$B:$B,K12),0) -> 1.212522 | R12: =H12-TODAY() -> 136 | S12: =IF(R12<0,"OVERDUE",IF(Q12>R12,"HIGH",IF(R12-Q12<3,"MEDIUM","LOW"))) -> LOW
A13: ORD-1112 | B13: Studio Firenze | C13: STY-004-1 | D13: Abito | E13: 320 | F13: 36-46 | G13: 46203 | H13: 46241 | I13: 46237 | J13: L8 | K13: LN-035 | L13: high | M13: quality control | N13: 0.4 | O13: =IFERROR(VLOOKUP(C13,style_master!$A:$H,8,FALSE),0) -> 48 | P13: =E13*O13 -> 15360 | Q13: =IFERROR(P13/SUMIFS(line_capacity!$N:$N,line_capacity!$A:$A,J13,line_capacity!$B:$B,K13),0) -> 4.2932274 | R13: =H13-TODAY() -> 72 | S13: =IF(R13<0,"OVERDUE",IF(Q13>R13,"HIGH",IF(R13-Q13<3,"MEDIUM","LOW"))) -> LOW
... A61: ORD-1160 | B61: Studio Firenze | C61: STY-011-2 | D61: Kimono | E61: 150 | F61: 70B-90D | G61: 46221 | H61: 46265 | I61: 46259 | J61: L2 | K61: LN-007 | L61: normal | M61: finishing | N61: 0.23 | O61: =IFERROR(VLOOKUP(C61,style_master!$A:$H,8,FALSE),0) -> 45 | P61: =E61*O61 -> 6750 | Q61: =IFERROR(P61/SUMIFS(line_capacity!$N:$N,line_capacity!$A:$A,J61,line_capacity!$B:$B,K61),0) -> 3.2150206 | R61: =H61-TODAY() -> 96 | S61: =IF(R61<0,"OVERDUE",IF(Q61>R61,"HIGH",IF(R61-Q61<3,"MEDIUM","LOW"))) -> LOW

Sheet product_matrix
A1: product_type | B1: phase_name | C1: line_type | D1: min_time_minutes | E1: max_time_minutes | F1: avg_time_minutes | G1: setup_time_minutes | H1: phase_order | I1: dependency
A2: Cappotto | B2: taglio tessuto | C2: cutting | D2: 10 | E2: 14 | F2: 12 | G2: 3 | H2: 1 | I2: tech pack approved
A3: Cappotto | B3: adesivazione | C3: cutting | D3: 7 | E3: 11 | F3: 9 | G3: 2 | H3: 2 | I3: previous phase
A4: Cappotto | B4: imbastitura | C4: sewing | D4: 10 | E4: 16 | F4: 13 | G4: 2 | H4: 3 | I4: previous phase
A5: Cappotto | B5: confezione capo | C5: sewing | D5: 28 | E5: 40 | F5: 34 | G5: 5 | H5: 4 | I5: previous phase
A6: Cappotto | B6: applicazione fodera | C6: sewing | D6: 14 | E6: 21 | F6: 18 | G6: 3 | H6: 5 | I6: previous phase
A7: Cappotto | B7: stiro intermedio | C7: finishing | D7: 5 | E7: 8 | F7: 6 | G7: 1 | H7: 6 | I7: previous phase
A8: Cappotto | B8: controllo qualità | C8: quality_control | D8: 4 | E8: 7 | F8: 5 | G8: 0.5 | H8: 7 | I8: previous phase
A9: Cappotto | B9: packing | C9: finishing | D9: 3 | E9: 5 | F9: 4 | G9: 0.5 | H9: 8 | I9: previous phase
A10: Gonna | B10: taglio tessuto | C10: cutting | D10: 5 | E10: 9 | F10: 7 | G10: 2 | H10: 1 | I10: tech pack approved
A11: Gonna | B11: applicazione zip | C11: sewing | D11: 5 | E11: 8 | F11: 6 | G11: 1 | H11: 2 | I11: previous phase
A12: Gonna | B12: confezione capo | C12: sewing | D12: 12 | E12: 18 | F12: 15 | G12: 3 | H12: 3 | I12: previous phase
A13: Gonna | B13: orlo | C13: sewing | D13: 4 | E13: 7 | F13: 5 | G13: 1 | H13: 4 | I13: previous phase
... A92: Baby doll | B92: controllo qualità | C92: quality_control | D92: 2 | E92: 4 | F92: 3 | G92: 0.5 | H92: 5 | I92: previous phase

Sheet labs_factories
A1: lab_id | B1: lab_name | C1: region | D1: city | E1: number_of_workers | F1: working_hours_per_day | G1: working_days_per_week | H1: default_efficiency | I1: machine_uptime | J1: max_weekly_hours | K1: overtime_allowed | L1: risk_level
A2: L1 | B2: Laboratorio Nord | C2: Lombardy | D2: Bergamo | E2: 55 | F2: 8 | G2: 5 | H2: 0.84 | I2: 0.92 | J2: 48 | K2: No | L2: Low
A3: L2 | B3: Laboratorio Veneto | C3: Veneto | D3: Vicenza | E3: 80 | F3: 8 | G3: 5 | H3: 0.81 | I3: 0.9 | J3: 48 | K3: Yes | L3: Medium
A4: L3 | B4: Laboratorio Centro | C4: Lazio | D4: Roma | E4: 70 | F4: 8 | G4: 5 | H4: 0.82 | I4: 0.9 | J4: 48 | K4: No | L4: Low
A5: L4 | B5: Laboratorio Est | C5: Emilia-Romagna | D5: Modena | E5: 95 | F5: 8 | G5: 5 | H5: 0.78 | I5: 0.89 | J5: 48 | K5: No | L5: Medium
A6: L5 | B6: Atelier Toscana | C6: Tuscany | D6: Prato | E6: 42 | F6: 8 | G6: 5 | H6: 0.79 | I6: 0.88 | J6: 45 | K6: No | L6: Low
A7: L6 | B7: Unità Sud | C7: Puglia | D7: Bari | E7: 110 | F7: 8 | G7: 5 | H7: 0.76 | I7: 0.87 | J7: 48 | K7: Yes | L7: Medium
A8: L7 | B8: Iberia Garments | C8: Porto | D8: Porto | E8: 180 | F8: 8 | G8: 5 | H8: 0.8 | I8: 0.91 | J8: 48 | K8: Yes | L8: Medium
A9: L8 | B9: Balkan Stitch | C9: Transylvania | D9: Cluj | E9: 140 | F9: 8 | G9: 5 | H9: 0.77 | I9: 0.88 | J9: 48 | K9: Yes | L9: Medium
A10: L9 | B10: Marmara Apparel | C10: Istanbul | D10: Istanbul | E10: 260 | F10: 8 | G10: 6 | H10: 0.82 | I10: 0.9 | J10: 54 | K10: Yes | L10: High
A11: L10 | B11: Tunis Craft Unit | C11: Tunis | D11: Tunis | E11: 210 | F11: 8 | G11: 5 | H11: 0.79 | I11: 0.89 | J11: 48 | K11: Yes | L11: Medium

Sheet line_capacity
A1: lab_id | B1: line_id | C1: line_type | D1: primary_product | E1: operators | F1: machines | G1: shift_hours | H1: days_per_week | I1: efficiency | J1: uptime | K1: overtime_allowed | L1: weekly_capacity_hours | M1: net_minutes_day | N1: available_smv_minutes_day
A2: L1 | B2: LN-001 | C2: cutting | D2: Pantalone | E2: 2 | F2: 1 | G2: 8 | H2: 5 | I2: 0.84 | J2: 0.92 | K2: No | L2: =G2*H2 -> 40 | M2: =E2*G2*60 -> 960 | N2: =M2*I2*J2 -> 741.888
A3: L1 | B3: LN-002 | C3: sewing | D3: Body | E3: 5 | F3: 5 | G3: 8 | H3: 5 | I3: 0.84 | J3: 0.92 | K3: No | L3: =G3*H3 -> 40 | M3: =E3*G3*60 -> 2400 | N3: =M3*I3*J3 -> 1854.72
A4: L1 | B4: LN-003 | C4: finishing | D4: Body | E4: 2 | F4: 2 | G4: 8 | H4: 5 | I4: 0.84 | J4: 0.92 | K4: No | L4: =G4*H4 -> 40 | M4: =E4*G4*60 -> 960 | N4: =M4*I4*J4 -> 741.888
A5: L1 | B5: LN-004 | C5: quality_control | D5: T-shirt | E5: 4 | F5: 0 | G5: 8 | H5: 5 | I5: 0.84 | J5: 0.92 | K5: No | L5: =G5*H5 -> 40 | M5: =E5*G5*60 -> 1920 | N5: =M5*I5*J5 -> 1483.776
A6: L1 | B6: LN-005 | C6: sampling | D6: Top | E6: 5 | F6: 3 | G6: 8 | H6: 5 | I6: 0.84 | J6: 0.92 | K6: No | L6: =G6*H6 -> 40 | M6: =E6*G6*60 -> 2400 | N6: =M6*I6*J6 -> 1854.72
A7: L2 | B7: LN-006 | C7: cutting | D7: Top | E7: 2 | F7: 1 | G7: 8 | H7: 5 | I7: 0.81 | J7: 0.9 | K7: Yes | L7: =G7*H7 -> 40 | M7: =E7*G7*60 -> 960 | N7: =M7*I7*J7 -> 699.84
A8: L2 | B8: LN-007 | C8: sewing | D8: Felpa | E8: 6 | F8: 6 | G8: 8 | H8: 5 | I8: 0.81 | J8: 0.9 | K8: Yes | L8: =G8*H8 -> 40 | M8: =E8*G8*60 -> 2880 | N8: =M8*I8*J8 -> 2099.52
A9: L2 | B9: LN-008 | C9: finishing | D9: Jeans | E9: 2 | F9: 2 | G9: 8 | H9: 5 | I9: 0.81 | J9: 0.9 | K9: Yes | L9: =G9*H9 -> 40 | M9: =E9*G9*60 -> 960 | N9: =M9*I9*J9 -> 699.84
A10: L2 | B10: LN-009 | C10: quality_control | D10: Top | E10: 4 | F10: 0 | G10: 8 | H10: 5 | I10: 0.81 | J10: 0.9 | K10: Yes | L10: =G10*H10 -> 40 | M10: =E10*G10*60 -> 1920 | N10: =M10*I10*J10 -> 1399.68
A11: L3 | B11: LN-010 | C11: cutting | D11: Kimono | E11: 3 | F11: 1 | G11: 8 | H11: 5 | I11: 0.82 | J11: 0.9 | K11: No | L11: =G11*H11 -> 40 | M11: =E11*G11*60 -> 1440 | N11: =M11*I11*J11 -> 1062.72
A12: L3 | B12: LN-011 | C12: sewing | D12: Felpa | E12: 5 | F12: 3 | G12: 8 | H12: 5 | I12: 0.82 | J12: 0.9 | K12: No | L12: =G12*H12 -> 40 | M12: =E12*G12*60 -> 2400 | N12: =M12*I12*J12 -> 1771.2
A13: L3 | B13: LN-012 | C13: finishing | D13: Gonna | E13: 5 | F13: 4 | G13: 8 | H13: 5 | I13: 0.82 | J13: 0.9 | K13: No | L13: =G13*H13 -> 40 | M13: =E13*G13*60 -> 2400 | N13: =M13*I13*J13 -> 1771.2
... A47: L10 | B47: LN-046 | C47: quality_control | D47: Bra | E47: 6 | F47: 0 | G47: 8 | H47: 5 | I47: 0.79 | J47: 0.89 | K47: No | L47: =G47*H47 -> 40 | M47: =E47*G47*60 -> 2880 | N47: =M47*I47*J47 -> 2024.928

Sheet phase_capacity
A1: lab_id | B1: phase_name | C1: line_type | D1: workers_total | E1: workers_assigned | F1: machines_total | G1: available_minutes_per_day | H1: efficiency | I1: uptime | J1: bottleneck_flag
A2: L1 | B2: adesivazione | C2: cutting | D2: 2 | E2: 2 | F2: 2 | G2: =E2*8*60*H2*I2 -> 741.888 | H2: 0.84 | I2: 0.92 | J2: =IF(G2<720,"Potential bottleneck","OK") -> OK
A3: L1 | B3: applicazione elastici | C3: sewing | D3: 4 | E3: 3 | F3: 2 | G3: =E3*8*60*H3*I3 -> 1112.832 | H3: 0.84 | I3: 0.92 | J3: =IF(G3<720,"Potential bottleneck","OK") -> OK
A4: L1 | B4: applicazione fodera | C4: sewing | D4: 3 | E4: 3 | F4: 2 | G4: =E4*8*60*H4*I4 -> 1112.832 | H4: 0.84 | I4: 0.92 | J4: =IF(G4<720,"Potential bottleneck","OK") -> OK
A5: L1 | B5: applicazione zip | C5: sewing | D5: 6 | E5: 4 | F5: 3 | G5: =E5*8*60*H5*I5 -> 1483.776 | H5: 0.84 | I5: 0.92 | J5: =IF(G5<720,"Potential bottleneck","OK") -> OK
A6: L1 | B6: asolatura/bottoni | C6: sewing | D6: 3 | E6: 3 | F6: 2 | G6: =E6*8*60*H6*I6 -> 1112.832 | H6: 0.84 | I6: 0.92 | J6: =IF(G6<720,"Potential bottleneck","OK") -> OK
A7: L1 | B7: assemblaggio | C7: sewing | D7: 6 | E7: 5 | F7: 4 | G7: =E7*8*60*H7*I7 -> 1854.72 | H7: 0.84 | I7: 0.92 | J7: =IF(G7<720,"Potential bottleneck","OK") -> OK
A8: L1 | B8: assemblaggio busto | C8: sewing | D8: 4 | E8: 3 | F8: 3 | G8: =E8*8*60*H8*I8 -> 1112.832 | H8: 0.84 | I8: 0.92 | J8: =IF(G8<720,"Potential bottleneck","OK") -> OK
A9: L1 | B9: bottoni automatici | C9: sewing | D9: 2 | E9: 1 | F9: 1 | G9: =E9*8*60*H9*I9 -> 370.944 | H9: 0.84 | I9: 0.92 | J9: =IF(G9<720,"Potential bottleneck","OK") -> Potential bottleneck
A10: L1 | B10: cappuccio/collo | C10: sewing | D10: 3 | E10: 3 | F10: 2 | G10: =E10*8*60*H10*I10 -> 1112.832 | H10: 0.84 | I10: 0.92 | J10: =IF(G10<720,"Potential bottleneck","OK") -> OK
A11: L1 | B11: cintura | C11: sewing | D11: 2 | E11: 2 | F11: 1 | G11: =E11*8*60*H11*I11 -> 741.888 | H11: 0.84 | I11: 0.92 | J11: =IF(G11<720,"Potential bottleneck","OK") -> OK
A12: L1 | B12: collo | C12: sewing | D12: 5 | E12: 3 | F12: 2 | G12: =E12*8*60*H12*I12 -> 1112.832 | H12: 0.84 | I12: 0.92 | J12: =IF(G12<720,"Potential bottleneck","OK") -> OK
A13: L1 | B13: collo e polsi | C13: sewing | D13: 4 | E13: 2 | F13: 2 | G13: =E13*8*60*H13*I13 -> 741.888 | H13: 0.84 | I13: 0.92 | J13: =IF(G13<720,"Potential bottleneck","OK") -> OK
... A374: L10 | B374: tasche | C374: sewing | D374: 2 | E374: 1 | F374: 1 | G374: =E374*8*60*H374*I374 -> 337.488 | H374: 0.79 | I374: 0.89 | J374: =IF(G374<720,"Potential bottleneck","OK") -> Potential bottleneck

Sheet TNA_calendar
A1: tna_id | B1: order_id | C1: milestone | D1: planned_date | E1: actual_date | F1: delay_days | G1: status | H1: critical_path
A2: TNA-001-01 | B2: ORD-1010 | C2: tech pack freeze | D2: 46144 | E2: 46144 | F2: =IF(E2="","",E2-D2) -> 0 | G2: =IF(E2="","Open",IF(F2>0,"Delayed","Done")) -> Done | H2: No
A3: TNA-001-02 | B3: ORD-1010 | C3: BOM final approval | D3: 46147 | F3: =IF(E3="","",E3-D3) | G3: =IF(E3="","Open",IF(F3>0,"Delayed","Done")) -> Open | H3: No
A4: TNA-001-03 | B4: ORD-1010 | C4: fabric booking | D4: 46149 | F4: =IF(E4="","",E4-D4) | G4: =IF(E4="","Open",IF(F4>0,"Delayed","Done")) -> Open | H4: No
A5: TNA-001-04 | B5: ORD-1010 | C5: trim booking | D5: 46151 | E5: 46154 | F5: =IF(E5="","",E5-D5) -> 3 | G5: =IF(E5="","Open",IF(F5>0,"Delayed","Done")) -> Delayed | H5: No
A6: TNA-001-05 | B6: ORD-1010 | C6: fit sample sent | D6: 46155 | E6: 46153 | F6: =IF(E6="","",E6-D6) -> -2 | G6: =IF(E6="","Open",IF(F6>0,"Delayed","Done")) -> Done | H6: No
A7: TNA-001-06 | B7: ORD-1010 | C7: fit approval | D7: 46161 | F7: =IF(E7="","",E7-D7) | G7: =IF(E7="","Open",IF(F7>0,"Delayed","Done")) -> Open | H7: No
A8: TNA-001-07 | B8: ORD-1010 | C8: size set sample | D8: 46165 | F8: =IF(E8="","",E8-D8) | G8: =IF(E8="","Open",IF(F8>0,"Delayed","Done")) -> Open | H8: No
A9: TNA-001-08 | B9: ORD-1010 | C9: PP sample approval | D9: 46171 | E9: 46174 | F9: =IF(E9="","",E9-D9) -> 3 | G9: =IF(E9="","Open",IF(F9>0,"Delayed","Done")) -> Delayed | H9: Yes
A10: TNA-001-09 | B10: ORD-1010 | C10: fabric in-house | D10: 46173 | E10: 46174 | F10: =IF(E10="","",E10-D10) -> 1 | G10: =IF(E10="","Open",IF(F10>0,"Delayed","Done")) -> Delayed | H10: Yes
A11: TNA-001-10 | B11: ORD-1010 | C11: bulk cutting start | D11: 46175 | F11: =IF(E11="","",E11-D11) | G11: =IF(E11="","Open",IF(F11>0,"Delayed","Done")) -> Open | H11: Yes
A12: TNA-001-11 | B12: ORD-1010 | C12: sewing start | D12: 46178 | F12: =IF(E12="","",E12-D12) | G12: =IF(E12="","Open",IF(F12>0,"Delayed","Done")) -> Open | H12: Yes
A13: TNA-001-12 | B13: ORD-1010 | C13: inline QC | D13: 46182 | E13: 46184 | F13: =IF(E13="","",E13-D13) -> 2 | G13: =IF(E13="","Open",IF(F13>0,"Delayed","Done")) -> Delayed | H13: No
A14: TNA-001-13 | B14: ORD-1010 | C14: finishing & pressing | D14: 46184 | F14: =IF(E14="","",E14-D14) | G14: =IF(E14="","Open",IF(F14>0,"Delayed","Done")) -> Open | H14: No
A15: TNA-001-14 | B15: ORD-1010 | C15: final inspection | D15: 46186 | E15: 46187 | F15: =IF(E15="","",E15-D15) -> 1 | G15: =IF(E15="","Open",IF(F15>0,"Delayed","Done")) -> Delayed | H15: Yes
A16: TNA-001-15 | B16: ORD-1010 | C16: packing | D16: 46187 | F16: =IF(E16="","",E16-D16) | G16: =IF(E16="","Open",IF(F16>0,"Delayed","Done")) -> Open | H16: No
A17: TNA-001-16 | B17: ORD-1010 | C17: ex-factory | D17: 46189 | E17: 46189 | F17: =IF(E17="","",E17-D17) -> 0 | G17: =IF(E17="","Open",IF(F17>0,"Delayed","Done")) -> Done | H17: Yes
A18: TNA-002-01 | B18: ORD-1011 | C18: tech pack freeze | D18: 46139 | E18: 46142 | F18: =IF(E18="","",E18-D18) -> 3 | G18: =IF(E18="","Open",IF(F18>0,"Delayed","Done")) -> Delayed | H18: No
A19: TNA-002-02 | B19: ORD-1011 | C19: BOM final approval | D19: 46142 | F19: =IF(E19="","",E19-D19) | G19: =IF(E19="","Open",IF(F19>0,"Delayed","Done")) -> Open | H19: No
A20: TNA-002-03 | B20: ORD-1011 | C20: fabric booking | D20: 46144 | F20: =IF(E20="","",E20-D20) | G20: =IF(E20="","Open",IF(F20>0,"Delayed","Done")) -> Open | H20: No
A21: TNA-002-04 | B21: ORD-1011 | C21: trim booking | D21: 46146 | F21: =IF(E21="","",E21-D21) | G21: =IF(E21="","Open",IF(F21>0,"Delayed","Done")) -> Open | H21: No
A22: TNA-002-05 | B22: ORD-1011 | C22: fit sample sent | D22: 46150 | E22: 46153 | F22: =IF(E22="","",E22-D22) -> 3 | G22: =IF(E22="","Open",IF(F22>0,"Delayed","Done")) -> Delayed | H22: No
A23: TNA-002-06 | B23: ORD-1011 | C23: fit approval | D23: 46156 | E23: 46156 | F23: =IF(E23="","",E23-D23) -> 0 | G23: =IF(E23="","Open",IF(F23>0,"Delayed","Done")) -> Done | H23: No
A24: TNA-002-07 | B24: ORD-1011 | C24: size set sample | D24: 46160 | E24: 46158 | F24: =IF(E24="","",E24-D24) -> -2 | G24: =IF(E24="","Open",IF(F24>0,"Delayed","Done")) -> Done | H24: No
A25: TNA-002-08 | B25: ORD-1011 | C25: PP sample approval | D25: 46166 | F25: =IF(E25="","",E25-D25) | G25: =IF(E25="","Open",IF(F25>0,"Delayed","Done")) -> Open | H25: Yes
A26: TNA-002-09 | B26: ORD-1011 | C26: fabric in-house | D26: 46168 | E26: 46168 | F26: =IF(E26="","",E26-D26) -> 0 | G26: =IF(E26="","Open",IF(F26>0,"Delayed","Done")) -> Done | H26: Yes
A27: TNA-002-10 | B27: ORD-1011 | C27: bulk cutting start | D27: 46170 | F27: =IF(E27="","",E27-D27) | G27: =IF(E27="","Open",IF(F27>0,"Delayed","Done")) -> Open | H27: Yes
A28: TNA-002-11 | B28: ORD-1011 | C28: sewing start | D28: 46173 | E28: 46173 | F28: =IF(E28="","",E28-D28) -> 0 | G28: =IF(E28="","Open",IF(F28>0,"Delayed","Done")) -> Done | H28: Yes
A29: TNA-002-12 | B29: ORD-1011 | C29: inline QC | D29: 46177 | E29: 46178 | F29: =IF(E29="","",E29-D29) -> 1 | G29: =IF(E29="","Open",IF(F29>0,"Delayed","Done")) -> Delayed | H29: No
A30: TNA-002-13 | B30: ORD-1011 | C30: finishing & pressing | D30: 46179 | E30: 46180 | F30: =IF(E30="","",E30-D30) -> 1 | G30: =IF(E30="","Open",IF(F30>0,"Delayed","Done")) -> Delayed | H30: No
A31: TNA-002-14 | B31: ORD-1011 | C31: final inspection | D31: 46181 | F31: =IF(E31="","",E31-D31) | G31: =IF(E31="","Open",IF(F31>0,"Delayed","Done")) -> Open | H31: Yes
A32: TNA-002-15 | B32: ORD-1011 | C32: packing | D32: 46182 | E32: 46180 | F32: =IF(E32="","",E32-D32) -> -2 | G32: =IF(E32="","Open",IF(F32>0,"Delayed","Done")) -> Done | H32: No
A33: TNA-002-16 | B33: ORD-1011 | C33: ex-factory | D33: 46184 | E33: 46184 | F33: =IF(E33="","",E33-D33) -> 0 | G33: =IF(E33="","Open",IF(F33>0,"Delayed","Done")) -> Done | H33: Yes
A34: TNA-003-01 | B34: ORD-1012 | C34: tech pack freeze | D34: 46147 | F34: =IF(E34="","",E34-D34) | G34: =IF(E34="","Open",IF(F34>0,"Delayed","Done")) -> Open | H34: No
A35: TNA-003-02 | B35: ORD-1012 | C35: BOM final approval | D35: 46150 | F35: =IF(E35="","",E35-D35) | G35: =IF(E35="","Open",IF(F35>0,"Delayed","Done")) -> Open | H35: No
A36: TNA-003-03 | B36: ORD-1012 | C36: fabric booking | D36: 46152 | E36: 46151 | F36: =IF(E36="","",E36-D36) -> -1 | G36: =IF(E36="","Open",IF(F36>0,"Delayed","Done")) -> Done | H36: No
A37: TNA-003-04 | B37: ORD-1012 | C37: trim booking | D37: 46154 | F37: =IF(E37="","",E37-D37) | G37: =IF(E37="","Open",IF(F37>0,"Delayed","Done")) -> Open | H37: No
A38: TNA-003-05 | B38: ORD-1012 | C38: fit sample sent | D38: 46158 | E38: 46161 | F38: =IF(E38="","",E38-D38) -> 3 | G38: =IF(E38="","Open",IF(F38>0,"Delayed","Done")) -> Delayed | H38: No
A39: TNA-003-06 | B39: ORD-1012 | C39: fit approval | D39: 46164 | E39: 46164 | F39: =IF(E39="","",E39-D39) -> 0 | G39: =IF(E39="","Open",IF(F39>0,"Delayed","Done")) -> Done | H39: No
A40: TNA-003-07 | B40: ORD-1012 | C40: size set sample | D40: 46168 | E40: 46171 | F40: =IF(E40="","",E40-D40) -> 3 | G40: =IF(E40="","Open",IF(F40>0,"Delayed","Done")) -> Delayed | H40: No
...

Sheet risk_register
A1: risk_id | B1: risk_area | C1: description | D1: probability | E1: impact | F1: risk_score | G1: mitigation | H1: owner | I1: linked_sheet | J1: status
A2: RISK-001 | B2: Material | C2: Main fabric arrival after planned cut date | D2: 4 | E2: 5 | F2: =D2*E2 -> 20 | G2: Book greige fabric earlier; create alternate supplier option | H2: Sourcing | I2: MRP_material_requirements | J2: Open
A3: RISK-002 | B3: Capacity | C3: Sewing line overloaded during same delivery week | D3: 3 | E3: 5 | F3: =D3*E3 -> 15 | G3: Rebalance between labs L3/L8; authorize overtime only for critical path | H3: Production | I3: orders / line_capacity | J3: Open
A4: RISK-003 | B4: Quality | C4: PP sample not approved before bulk start | D4: 3 | E4: 4 | F4: =D4*E4 -> 12 | G4: No bulk cutting before PP approval; daily approval tracker | H4: Product Dev | I4: TNA_calendar | J4: Monitoring
A5: RISK-004 | B5: Supplier | C5: High-risk supplier has long payment confirmation cycle | D5: 2 | E5: 4 | F5: =D5*E5 -> 8 | G5: Switch to Net 30 preferred suppliers; pre-approve POs | H5: Merchandising | I5: suppliers | J5: Open
A6: RISK-005 | B6: Data | C6: Tech pack version mismatch between BOM and factory | D6: 3 | E6: 5 | F6: =D6*E6 -> 15 | G6: Freeze version IDs; use one source of truth for style master | H6: Technical Office | I6: style_master | J6: Open
A7: RISK-006 | B7: Sustainability | C7: Claim not backed by certificate at shipment | D7: 2 | E7: 4 | F7: =D7*E7 -> 8 | G7: Attach certificate to material master and PO before launch | H7: Compliance | I7: materials_inventory | J7: Monitoring

Sheet data_dictionary
A1: sheet | B1: field | C1: description | D1: type | E1: logic
A2: orders | B2: order_id | C2: Unique production order identifier | D2: Text | E2: Required
A3: orders | B3: planned_smv | C3: Standard minutes per garment pulled from style master | D3: Formula | E3: VLOOKUP from style_master
A4: orders | B4: capacity_days_needed | C4: Total standard minutes divided by assigned line daily available minutes | D4: Formula | E4: Uses line_capacity
A5: product_matrix | B5: avg_time_minutes | C5: Average operation time in minutes | D5: Number | E5: Based on SMV/SAM logic
A6: line_capacity | B6: available_smv_minutes_day | C6: Net daily minutes adjusted by efficiency and uptime | D6: Formula | E6: Operators × shift hours × 60 × efficiency × uptime
A7: BOM | B7: usage_qty_per_garment | C7: Component consumption per garment | D7: Number | E7: Per style/component
A8: MRP_material_requirements | B8: purchase_needed_qty | C8: Required qty minus available material stock | D8: Formula | E8: MAX(0, requirement-stock)
A9: TNA_calendar | B9: delay_days | C9: Actual date minus planned date | D9: Formula | E9: Blank if actual date missing
A10: phase_capacity | B10: bottleneck_flag | C10: Flags phases with low available minutes | D10: Formula | E10: Threshold based
